Workbook

Sheet Resumen
A1: Matriz de revisión del Avance 1 – Proyecto Integrador Matemática II
A2: Revisión por pares con criterio de revista Q1 de la problemática, pregunta de investigación, hipótesis y objetivos. Fecha de revisión: 16-oct-2026. Revisor: Ing. Guillermo Chuncho. Nómina: Grupos/Grupos_matematica.xlsx; asignación de tema y zona: guía general del proyecto integrador (Cuadro 1). Datos verificados contra las bases de Unidad_1/base_de_datos.
A4: Grupo | B4: Integrantes | C4: Tema y zona oficial | D4: Declarado en el informe | E4: Archivo revisado | F4: Problemática | G4: Pts. (/2,5) | H4: Pregunta | I4: Pts. (/2,5) | J4: Hipótesis | K4: Pts. (/2,5) | L4: Objetivos | M4: Pts. (/2,5) | N4: Calificación (/10) | O4: Equivalencia Fase 1 (/0,30) | P4: Dictamen | Q4: N.º obs. (Crít./May./Men.) | R4: Prioridades para el Avance 2
A5: 1 | B5: Jhanine Fernanda Toledo Merino Mayerly Stefanny Moreno Vera Mateo Joel Gonzalez Samaniego Dulce Isabel Barreto Zapata | C5: Relieve y accesibilidad – Zona Norte (Grupo_01_Relieve_Norte.csv) | D5: — | E5: No se encontró entrega en la carpeta avance_1 | F5: No presentado | G5: 0 | H5: No presentado | I5: 0 | J5: No presentado | K5: 0 | L5: No presentado | M5: 0 | N5: =G5+I5+K5+M5 -> 0 | O5: =ROUND(N5*0.03,2) -> 0 | P5: Sin entrega | Q5: 1/0/0 | R5: Entregar en el Avance 2 la formulación completa (problema, pregunta, hipótesis, objetivos) junto con los componentes propios del Avance 2.
A6: 2 | B6: Yanira Maily Rojas Vega Sonia Noemi Rodriguez Jaramillo Carlos Daniel Gonzalez Castillo Diana Patricia Cardenas Campoverde | C6: Relieve y accesibilidad – Zona Sur (Grupo_02_Relieve_Sur.csv) | D6: «Equipo N.º 1» – Relieve, Zona Norte | E6: Proyecto_de_integracion_grupo_1_Matematicas (1).pdf | F6: Revisión mayor | G6: 1.25 | H6: Reformular | I6: 0.75 | J6: Reformular | K6: 0.75 | L6: Revisión mayor | M6: 1 | N6: =G6+I6+K6+M6 -> 3.75 | O6: =ROUND(N6*0.03,2) -> 0.11 | P6: Revisión mayor | Q6: 1/7/1 | R6: 1) Confirmar grupo, zona y base. 2) Reescribir pregunta, hipótesis y objetivos en clave de cálculo integral (perfil de elevación de un transecto). 3) Eliminar lo que la base no mide (inundaciones, recarga hídrica, rutas reales).
A7: 3 | B7: John David Jimenez Troya Isidro Francisco Chamba Mendoza Andy Alcides Aguilar Arteaga Giorgi Michael Chamba Sanchez Kevin Josue Jimenez Macau | C7: Cobertura vegetal y uso del suelo – Zona Norte (Grupo_03_Cobertura_Norte.csv) | D7: «Equipo N.º 2» – Relieve, Zona Sur | E7: Avance_Proyecto_Matematicas_Grupo2 (1).pdf | F7: Reformular | G7: 1 | H7: Reformular | I7: 0.75 | J7: Reformular | K7: 1 | L7: Revisión mayor | M7: 1.5 | N7: =G7+I7+K7+M7 -> 4.25 | O7: =ROUND(N7*0.03,2) -> 0.13 | P7: Revisión mayor | Q7: 3/4/1 | R7: 1) Confirmar grupo, tema y base. 2) Abandonar la «variación mensual de la pendiente» (variable estática: vale 0). 3) Reconstruir la formulación desde el OE3 (integral del perfil de un transecto) o desde el tema oficial.
A8: 4 | B8: Barbara Salome Saritama Maldonado Yulian Jeraldine Guaman Aguirre Kristel Pauleth Cevallos Azanza Ana Gabriela Medina Yaguana | C8: Cobertura vegetal y uso del suelo – Zona Sur (Grupo_04_Cobertura_Sur.csv) | D8: «Equipo N.º 4» – Cobertura vegetal, Zona Sur (coincide) | E8: Relieve_y_Accesibilidad_Territorial__Sur_ (1) (2).pdf | F8: Revisión mayor | G8: 1.5 | H8: Reformular | I8: 1.25 | J8: Revisión mayor | K8: 1.5 | L8: Revisión menor | M8: 2 | N8: =G8+I8+K8+M8 -> 6.25 | O8: =ROUND(N8*0.03,2) -> 0.19 | P8: Revisión mayor | Q8: 2/3/2 | R8: 1) Distinguir A(t) (NDVI observado) de r(t) (tasa). 2) Declarar y tratar los NDVI faltantes (ninguna celda tiene 72 meses). 3) Convertir la hipótesis en una afirmación ambiental con umbral justificado.
A9: 5 | B9: Shislayne Azucena Chalan Jumbo Yurixi Maribel Riofrio Medina Jamileth Stefania Galvez Cornejo Ibelia Araceli Japon Caillagua Nelson Sebastian Pullaguari Cuenca | C9: Clima y condiciones atmosféricas – Zona Norte (Grupo_05_Clima_Norte.csv) | D9: «Equipo N.º 5» – Clima, Zona Norte (coincide) | E9: informe_parte1-1.pdf e informe_parte_matemática 2.pdf (idénticos) | F9: Reformular | G9: 1 | H9: Revisión mayor | I9: 1.5 | J9: Reformular | K9: 1 | L9: Revisión mayor | M9: 1.25 | N9: =G9+I9+K9+M9 -> 4.75 | O9: =ROUND(N9*0.03,2) -> 0.14 | P9: Revisión mayor | Q9: 1/6/0 | R9: 1) Corregir el uso del TFC (H(t₂) − H(t₁), no «valores extremos»). 2) Reescribir la hipótesis: la suma mensual ya es la integral exacta. 3) Redacción técnica y completar las secciones de plantilla.
A10: 6 | B10: Sara Lissette Criollo Montalvan Lady Lissethe Medina Gualan Lisseth Alexandra Salazar Valdiviezo Alejandra Nicole Verdesoto Ortiz Lisbeth Liliana Sandoval Mendoza | C10: Clima y condiciones atmosféricas – Zona Sur (Grupo_06_Clima_Sur.csv) | D10: «Equipo 6» – Clima, Zona Sur (coincide) | E10: Avance1_proyecto_integrador_Matematica2_Equipo6.pdf | F10: No presentado | G10: 0.5 | H10: Revisión mayor | I10: 1.5 | J10: No presentado | K10: 0 | L10: No presentado | M10: 0 | N10: =G10+I10+K10+M10 -> 2 | O10: =ROUND(N10*0.03,2) -> 0.06 | P10: Rechazo y reenvío | Q10: 4/2/1 | R10: 1) Redactar problemática, justificación, hipótesis y objetivos (no se entregaron). 2) Dejar una sola pregunta (volumen pluvial); la fuerza hidrostática es de la Unidad 3. 3) Corregir la notación P, p(t), H(t).
A11: 7 | B11: Adrian Saul Aguilar Franco Diana Carolina Llivisaca Montoya Jhonny Francisco Narvaez Macas Jorge Isai Landacay Hidalgo Carlos Daniel Cajamarca Gordillo | C11: Incendios forestales y riesgo – Cantón completo (Grupo_07_Incendios_Loja.xlsx) | D11: — | E11: No se encontró entrega en la carpeta avance_1 | F11: No presentado | G11: 0 | H11: No presentado | I11: 0 | J11: No presentado | K11: 0 | L11: No presentado | M11: 0 | N11: =G11+I11+K11+M11 -> 0 | O11: =ROUND(N11*0.03,2) -> 0 | P11: Sin entrega | Q11: 1/0/0 | R11: Entregar en el Avance 2 la formulación completa (problema, pregunta, hipótesis, objetivos) junto con los componentes propios del Avance 2.
A13: Calificación: cada elemento se puntúa sobre 2,5 (ver hoja «Criterios de revisión»). Calificación = suma de los cuatro puntajes (/10). Equivalencia en la Fase 1 = calificación × 0,03 (máx. 0,30 pts). Si se modifica un puntaje en esta hoja, la calificación se actualiza en todas las hojas.
A14: Escala de dictamen
A15: Adecuado | C15: Cumple; solo ajustes de estilo.
A16: Revisión menor | C16: Correcciones puntuales que no alteran el planteamiento.
A17: Revisión mayor | C17: Requiere reformular uno o más elementos; el proyecto es viable.
A18: Reformular | C18: El elemento no es válido o no es respondible con la base; debe rehacerse.
A19: No presentado | C19: El elemento no aparece en el documento.
A20: Rechazo y reenvío | C20: Faltan componentes esenciales; reenviar completo en el Avance 2.
A21: Sin entrega | C21: No se encontró documento del grupo.

Sheet Matriz consolidada
A1: Matriz consolidada de observaciones – Avance 1
A2: Revisión por pares con criterio de revista Q1 de la problemática, pregunta de investigación, hipótesis y objetivos. Fecha de revisión: 16-oct-2026. Revisor: Ing. Guillermo Chuncho. Nómina: Grupos/Grupos_matematica.xlsx; asignación de tema y zona: guía general del proyecto integrador (Cuadro 1). Datos verificados contra las bases de Unidad_1/base_de_datos. Use los filtros para ver su grupo.
A4: Grupo | B4: Integrantes | C4: Calificación del grupo (/10) | D4: N.º | E4: Elemento | F4: Severidad | G4: Evidencia en el informe | H4: Error o debilidad detectada | I4: Sugerencia para el Avance 2 | J4: Ejemplo orientativo (adaptar, no copiar)
A5: 1 | B5: Jhanine Fernanda Toledo Merino, Mayerly Stefanny Moreno Vera, Mateo Joel Gonzalez Samaniego, Dulce Isabel Barreto Zapata | C5: =Resumen!N5 -> 0 | D5: 1 | E5: General | F5: Crítica | G5: No existe archivo del grupo en Unidad_1/avance_proyecto_integrador/avance_1. | H5: No hay evidencia del Avance 1: no puede evaluarse problemática, pregunta, hipótesis ni objetivos. | I5: Si la entrega se realizó por otro medio (EVA, correo), comunicarlo al docente. Caso contrario, el Avance 2 debe incluir la formulación completa: problema, pregunta, hipótesis y objetivos, siguiendo la guía general (sección 4.4, Unidad 1) y la guía del Avance 2.
A6: 1 | B6: Jhanine Fernanda Toledo Merino, Mayerly Stefanny Moreno Vera, Mateo Joel Gonzalez Samaniego, Dulce Isabel Barreto Zapata | C6: =Resumen!N5 -> 0 | D6: 2 | E6: Orientación | F6: Administrativa | G6: Tema asignado: relieve y accesibilidad, Zona Norte (400 celdas estáticas). | H6: — | I6: Recuerden que las variables de relieve son estáticas (una fila por celda): no tienen dimensión temporal. La guía general orienta el trabajo hacia el área bajo el perfil de elevación de un transecto, A = ∫ f(x) dx.
A7: 2 | B7: Yanira Maily Rojas Vega, Sonia Noemi Rodriguez Jaramillo, Carlos Daniel Gonzalez Castillo, Diana Patricia Cardenas Campoverde | C7: =Resumen!N6 -> 3.75 | D7: 1 | E7: Asignación | F7: Crítica | G7: Portada: «Equipo N.º 1 … parte norte del cantón Loja». | H7: En la nómina oficial (Grupos_matematica.xlsx y Cuadro 1 de la guía general) el grupo figura como GRUPO 2, con el tema Relieve y la Zona SUR. El informe se declara Equipo 1 y trabaja la Zona Norte. | I7: Confirmar con el docente el número de grupo y la base asignada antes del Avance 2. Si corresponde la Zona Sur, rehacer la delimitación con Grupo_02_Relieve_Sur.csv (centro_y_m < 9 555 250).
A8: 2 | B8: Yanira Maily Rojas Vega, Sonia Noemi Rodriguez Jaramillo, Carlos Daniel Gonzalez Castillo, Diana Patricia Cardenas Campoverde | C8: =Resumen!N6 -> 3.75 | D8: 2 | E8: Problemática | F8: Mayor | G8: Enumera cuatro causas: expansión urbana, escorrentía, inundaciones en zonas bajas y accesibilidad; menciona recarga hídrica, calidad del agua y caudal pico. | H8: El problema es descriptivo y disperso: mezcla fenómenos que la base no mide (escorrentía, inundaciones, recarga de acuíferos, expansión urbana, calidad del agua). La base contiene solo elevación, pendiente, orientación y distancias a vías y asentamientos, todas estáticas. El lector no identifica cuál es el problema investigable. | I8: Reducir el problema a una sola cadena: situación territorial (relieve quebrado) → vacío (no se ha cuantificado la sección transversal ni el desnivel acumulado de un transecto representativo) → relevancia → posibilidad de calcularlo con la base. Eliminar las causas que no pueden contrastarse con los datos.
A9: 2 | B9: Yanira Maily Rojas Vega, Sonia Noemi Rodriguez Jaramillo, Carlos Daniel Gonzalez Castillo, Diana Patricia Cardenas Campoverde | C9: =Resumen!N6 -> 3.75 | D9: 3 | E9: Problemática | F9: Mayor | G9: «Altitudes desde 2,400 m s.n.m. hasta 3,200+ m», «precipitación anual 900-1,200 mm», «temperaturas medias entre 9 °C y 16 °C». | H9: Son cifras de contexto sin cita, y contradicen la base: en la ventana Norte (Grupo_01_Relieve_Norte.csv) la elevación media por celda va de ≈1 643 m a ≈3 292 m. Además se listan siete parroquias (San Lucas, Santiago, Gualel, Taquil, Chantaco, Chuquiribamba, El Cisne) que no corresponden a una ventana de 10 × 10 km. | I9: Citar toda cifra de contexto (APA 7) y describir la zona con los datos reales de la ventana (rango de elevación, pendiente media, coordenadas). Delimitar el área a la ventana de 20 × 20 celdas, no a parroquias completas.
A10: 2 | B10: Yanira Maily Rojas Vega, Sonia Noemi Rodriguez Jaramillo, Carlos Daniel Gonzalez Castillo, Diana Patricia Cardenas Campoverde | C10: =Resumen!N6 -> 3.75 | D10: 4 | E10: Pregunta | F10: Mayor | G10: «¿Cómo influyen las características del terreno en el acceso a las diferentes zonas del norte de Loja durante el periodo 2019-2024…?» | H10: (a) La pregunta es causal y abierta («¿cómo influyen?»), no se responde con un número. (b) No está planteada en clave de cálculo integral: no hay función, intervalo ni integral, y la rúbrica de la Fase 1 lo exige. (c) «Accesibilidad» no está definida operativamente. (d) El periodo 2019-2024 no aplica: el relieve es estático. | I10: Formular una pregunta única, cuantitativa y respondible con una integral definida sobre un transecto de la ventana. | J10: Ejemplo orientativo (adaptar): ¿Cuál es el área de la sección transversal bajo el perfil de elevación del transecto [fila/columna] de la ventana [zona], A = ∫ₐᵇ f(x) dx (m²), y cuánto difiere su valor analítico de la aproximación trapezoidal con los 20 puntos observados?
A11: 2 | B11: Yanira Maily Rojas Vega, Sonia Noemi Rodriguez Jaramillo, Carlos Daniel Gonzalez Castillo, Diana Patricia Cardenas Campoverde | C11: =Resumen!N6 -> 3.75 | D11: 5 | E11: Hipótesis | F11: Mayor | G11: «…influyen de forma significativa en la accesibilidad… presentan mayores limitaciones de acceso (rutas más largas y sinuosas, con una distancia real mayor que la euclidiana)…» | H11: (a) «Significativa» no tiene indicador, umbral ni prueba asociados. (b) La base no contiene rutas ni distancias recorridas: solo la distancia euclidiana a la vía más cercana (osm_distancia_vias_m_mean). La comparación distancia real vs. euclidiana no es contrastable. (c) «Se concentran en sectores específicos que pueden localizarse» no es falsable. | I11: Escribir una afirmación con variable, transecto, indicador y criterio cuantitativo justificado. Si se mantiene la accesibilidad, operacionalizarla con osm_distancia_vias_m_mean y pendiente, y dejar la longitud de arco para la Unidad 2. | J11: Ejemplo orientativo: «Un polinomio de grado ≤ 4 ajustado al perfil del transecto reproduce la elevación con R² ≥ 0,95, y su integral difiere menos de 2 % de la suma trapezoidal con Δx = 500 m».
A12: 2 | B12: Yanira Maily Rojas Vega, Sonia Noemi Rodriguez Jaramillo, Carlos Daniel Gonzalez Castillo, Diana Patricia Cardenas Campoverde | C12: =Resumen!N6 -> 3.75 | D12: 6 | E12: Objetivos | F12: Mayor | G12: OG «Analizar cómo las características del relieve influyen…»; OE «Reconocer…», «Analizar cómo se relacionan…», «Localizar las áreas…». | H12: Los verbos no son medibles y ningún objetivo produce una salida verificable (tabla, valor, figura). El OG repite la pregunta. Ningún objetivo menciona un modelo f(x), una integral definida, sumas de Riemann o el TFC: el proyecto no demanda cálculo integral. | I12: OG en infinitivo, alineado con la nueva pregunta. Tres OE con salida verificable: (1) seleccionar y justificar el transecto (perfil observado); (2) ajustar f(x) y reportar R²/RMSE; (3) calcular ∫ f(x) dx analíticamente y compararla con Riemann/trapecio (error relativo %).
A13: 2 | B13: Yanira Maily Rojas Vega, Sonia Noemi Rodriguez Jaramillo, Carlos Daniel Gonzalez Castillo, Diana Patricia Cardenas Campoverde | C13: =Resumen!N6 -> 3.75 | D13: 7 | E13: Formato / completitud | F13: Mayor | G13: Las secciones 6 (Datos y variables), 7 (Alcance), 8 (Matriz de coherencia) y el anexo de IA conservan el texto de plantilla («nombre 1 …», «Qué incluye y qué no…»). | H13: El documento se entregó con secciones de plantilla sin completar. | I13: Completar o retirar toda sección de plantilla. La matriz de coherencia es especialmente útil para verificar que pregunta, hipótesis y OG traten la misma variable.
A14: 2 | B14: Yanira Maily Rojas Vega, Sonia Noemi Rodriguez Jaramillo, Carlos Daniel Gonzalez Castillo, Diana Patricia Cardenas Campoverde | C14: =Resumen!N6 -> 3.75 | D14: 8 | E14: Referencias | F14: Mayor | G14: INAMHI (2020) Anuario Meteorológico; GAD Provincial (2021) PDOT; Cueva y Jiménez (2019) «…sector sur del cantón Loja», Revista de Geografía y Ciencias Ambientales – UNL. | H14: No hay citas en el texto. El anuario meteorológico no sustenta afirmaciones sobre relieve. La referencia de Cueva y Jiménez (2019) trata el sector sur y no pudo localizarse; debe verificarse que exista. No se citan las fuentes de los datos (ALOS, OSM, GHSL). | I14: Citar en el texto cada afirmación con su fuente; incluir solo referencias consultadas y localizables (DOI/URL), y citar la base y el diccionario de variables del curso.
A15: 2 | B15: Yanira Maily Rojas Vega, Sonia Noemi Rodriguez Jaramillo, Carlos Daniel Gonzalez Castillo, Diana Patricia Cardenas Campoverde | C15: =Resumen!N6 -> 3.75 | D15: 9 | E15: Problemática | F15: Menor | G15: Las secciones 1 y 2 repiten casi literalmente los mismos párrafos (expansión urbana, erosión, accesibilidad). | H15: Hay redundancia entre problema y justificación; la lista numerada está incrustada en el párrafo, con errores de tipeo («rígos») y de puntuación. | I15: El problema explica qué falta conocer; la justificación explica por qué importa. No repetir. Usar listas de LaTeX (enumerate) o redactar en prosa.
A16: 3 | B16: John David Jimenez Troya, Isidro Francisco Chamba Mendoza, Andy Alcides Aguilar Arteaga, Giorgi Michael Chamba Sanchez, Kevin Josue Jimenez Macau | C16: =Resumen!N7 -> 4.25 | D16: 1 | E16: Asignación | F16: Crítica | G16: Portada: «Equipo N.º 2 … zona sur»; tema relieve y movilidad. | H16: En la nómina oficial el grupo es el GRUPO 3, con el tema Cobertura vegetal y uso del suelo, Zona NORTE. El informe trabaja relieve en la Zona Sur, tema asignado a otro grupo (en la guía general, la regla territorial prohíbe cruzar datos entre zonas o equipos). | I16: Confirmar con el docente el tema y la base. Si se mantiene la asignación oficial, el Avance 2 debe reformularse sobre Grupo_03_Cobertura_Norte.csv.
A17: 3 | B17: John David Jimenez Troya, Isidro Francisco Chamba Mendoza, Andy Alcides Aguilar Arteaga, Giorgi Michael Chamba Sanchez, Kevin Josue Jimenez Macau | C17: =Resumen!N7 -> 4.25 | D17: 2 | E17: Datos | F17: Crítica | G17: «base asignada al equipo 02 (3.996 celdas y 66 columnas)», «base mensual», variables dem_mean, slope_mean, dist_vias_m, dist_asentamientos_m. | H17: Se utilizó la base antigua (origen2), no la vigente. La base vigente de relieve tiene 400 celdas × 17 columnas, sin dimensión temporal, y sus columnas se llaman alos_elevacion_m_mean, alos_pendiente_grados_mean, osm_distancia_vias_m_mean y ghsl_distancia_asentamiento_m_mean. Las variables citadas no existen en ninguna base del curso. | I17: Trabajar únicamente con la base vigente de Unidad_1/base_de_datos y transcribir los nombres exactos de columna desde DICCIONARIO_VARIABLES.csv.
A18: 3 | B18: John David Jimenez Troya, Isidro Francisco Chamba Mendoza, Andy Alcides Aguilar Arteaga, Giorgi Michael Chamba Sanchez, Kevin Josue Jimenez Macau | C18: =Resumen!N7 -> 4.25 | D18: 3 | E18: Problemática | F18: Crítica | G18: «…se propone cuantificar los cambios mensuales de esa variable [pendiente] en cada celda…» | H18: La premisa es físicamente inválida: la pendiente proviene de un modelo digital de elevación estático (ALOS). En la base antigua el valor se repetía cada mes, así que |s_i,t − s_i,t−1| = 0 y V_i = 0 en todas las celdas. No existe un fenómeno que medir: la pregunta, la hipótesis y el OE2 no son respondibles. | I18: Descartar la «variación acumulada de la pendiente». Un problema viable con relieve es la caracterización integral de un transecto (área de la sección transversal, desnivel). Con cobertura, el problema es el cambio acumulado del NDVI.
A19: 3 | B19: John David Jimenez Troya, Isidro Francisco Chamba Mendoza, Andy Alcides Aguilar Arteaga, Giorgi Michael Chamba Sanchez, Kevin Josue Jimenez Macau | C19: =Resumen!N7 -> 4.25 | D19: 4 | E19: Pregunta | F19: Mayor | G19: «¿Qué asociación existe entre la variación acumulada de la pendiente media … y la distancia a las vías…?» | H19: (a) Depende de una variable con varianza nula, así que la correlación queda indefinida. (b) Es una pregunta estadística, no de cálculo integral: la integral aparece solo en el OE3. (c) Hay incoherencia: el OG incluye la integral del transecto, pero la pregunta y la hipótesis no. | I19: Reformular la pregunta alrededor de la integral definida (la parte más sólida del documento es el OE3). | J19: Ejemplo orientativo (si se confirma relieve): ¿Cuál es el área de la sección transversal ∫ₐᵇ f(x) dx bajo el perfil de elevación de un transecto desde el punto más bajo hasta la cumbre de la ventana, y cuál es el error relativo de las sumas de Riemann con n = 19 subintervalos?
A20: 3 | B20: John David Jimenez Troya, Isidro Francisco Chamba Mendoza, Andy Alcides Aguilar Arteaga, Giorgi Michael Chamba Sanchez, Kevin Josue Jimenez Macau | C20: =Resumen!N7 -> 4.25 | D20: 5 | E20: Hipótesis | F20: Mayor | G20: «…se asocia positivamente con la distancia a las vías… r ≥ 0,30 y p < 0,05.» | H20: Tiene una buena estructura formal (indicador, umbral y criterio de significancia), pero se aplica a una variable inexistente. El umbral r ≥ 0,30 no se justifica. Con celdas vecinas, la dependencia espacial infla el valor p (el equipo lo reconoce, pero no lo resuelve). | I20: Conservar la estructura (indicador + umbral + criterio) y aplicarla a una magnitud integral. Justificar el umbral con literatura o con la revisión preliminar.
A21: 3 | B21: John David Jimenez Troya, Isidro Francisco Chamba Mendoza, Andy Alcides Aguilar Arteaga, Giorgi Michael Chamba Sanchez, Kevin Josue Jimenez Macau | C21: =Resumen!N7 -> 4.25 | D21: 6 | E21: Objetivos | F21: Mayor | G21: OG compuesto: «Cuantificar… y analizar… complementando con la integral definida…». OE1: revisar estructura y calidad. OE3: transecto, f(x), antiderivada y Riemann. | H21: El OG reúne tres metas distintas. El OE1 es una tarea (revisión de datos) sin salida explícita. El OE2 es inviable. El OE3 está bien construido: tiene intervalo, nivel de referencia, antiderivada, comparación con Riemann e interpretación física. | I21: Construir el OG a partir del OE3. Expresar el OE1 como salida (tabla de control de calidad). Reemplazar el OE2 por el ajuste y la validación del modelo f(x) (R², RMSE).
A22: 3 | B22: John David Jimenez Troya, Isidro Francisco Chamba Mendoza, Andy Alcides Aguilar Arteaga, Giorgi Michael Chamba Sanchez, Kevin Josue Jimenez Macau | C22: =Resumen!N7 -> 4.25 | D22: 7 | E22: Formato / completitud | F22: Mayor | G22: El documento termina en el anexo de IA; no hay referencias, tabla de variables, alcance ni matriz de coherencia. Anexo IA: «El equipo debe verificar la exactitud de los datos…». | H22: No hay ninguna referencia bibliográfica ni cita. La declaración de IA está redactada como una instrucción dirigida al equipo (parece texto generado y no editado), no como una declaración de lo que el equipo verificó. | I22: Incluir referencias APA 7 localizables y la tabla de variables con nombres reales. Reescribir el anexo de IA en primera persona del plural: qué herramienta se usó, para qué, qué se verificó y qué se reescribió.
A23: 3 | B23: John David Jimenez Troya, Isidro Francisco Chamba Mendoza, Andy Alcides Aguilar Arteaga, Giorgi Michael Chamba Sanchez, Kevin Josue Jimenez Macau | C23: =Resumen!N7 -> 4.25 | D23: 8 | E23: Problemática | F23: Menor | G23: Redacción cuidadosa: distingue asociación de causalidad y declara qué no mide la base. | H23: Fortaleza que debe conservarse. Sin embargo, el problema no establece un vacío de conocimiento ambiental, sino un procedimiento de cálculo. | I23: Mantener el tono prudente y explicitar el vacío: qué no se sabe del territorio y por qué una integral lo resuelve.
A24: 4 | B24: Barbara Salome Saritama Maldonado, Yulian Jeraldine Guaman Aguirre, Kristel Pauleth Cevallos Azanza, Ana Gabriela Medina Yaguana | C24: =Resumen!N8 -> 6.25 | D24: 1 | E24: Datos | F24: Crítica | G24: «…un período ininterrumpido de 72 meses … 7.200 registros», «a partir de los 72 registros mensuales disponibles». | H24: Es falso para el NDVI: faltan 1 412 de 7 200 valores (19,6 %), ninguna celda tiene los 72 meses completos (el mínimo es 46) y en 2019-01, 2023-03 y 2023-05 falta el NDVI en las 100 celdas. El ajuste y las integrales dependen críticamente de cómo se traten estos huecos. | I24: Cuantificar los faltantes por mes y por celda (sentinel_t1_missing, s2_cobertura_valida_pct) y declarar el tratamiento: excluir, promediar espacialmente las celdas válidas o interpolar con justificación. Reportar cuántas observaciones entran en cada cálculo.
A25: 4 | B25: Barbara Salome Saritama Maldonado, Yulian Jeraldine Guaman Aguirre, Kristel Pauleth Cevallos Azanza, Ana Gabriela Medina Yaguana | C25: =Resumen!N8 -> 6.25 | D25: 2 | E25: Pregunta | F25: Crítica | G25: «¿Cuál es la variación neta acumulada … A_veg = ∫ r(t) dt …? Asimismo, ¿qué grado de concordancia existe entre … sumas de Riemann … y … el TFC, utilizando un modelo continuo r(t)…?» | H25: (a) Son dos preguntas. (b) Hay una confusión conceptual entre A(t) y r(t): la base observa el nivel A(t) (NDVI), no la tasa r(t). Por el TFC, ∫r dt = A(72) − A(1): el «cambio neto» se reduce a la diferencia entre dos meses ruidosos (y uno de ellos, 2019-01, no tiene datos). (c) Para aplicar Riemann a r(t) primero hay que construir r a partir de diferencias finitas, y eso no se explica. | I25: Elegir una sola formulación coherente: (a) integrar el NDVI observado, V = ∫ A(t) dt [NDVI·mes] («verdor acumulado»), y comparar el modelo continuo con el trapecio; o (b) definir r(t) ≈ ΔA/Δt, modelarla y verificar el TFC con A(t₂) − A(t₁) usando promedios de periodo en lugar de meses aislados. Dejar una sola pregunta.
A26: 4 | B26: Barbara Salome Saritama Maldonado, Yulian Jeraldine Guaman Aguirre, Kristel Pauleth Cevallos Azanza, Ana Gabriela Medina Yaguana | C26: =Resumen!N8 -> 6.25 | D26: 3 | E26: Problemática | F26: Mayor | G26: «Este cantón abarca alrededor de 1.928 km² … agrícolas (31 %), bosque nativo (26 %), matorrales (17 %)…». «…las fluctuaciones … de la temperatura y la precipitación provocan períodos de escasez de agua que pueden impactar … la actividad fotosintética…» | H26: Las cifras de contexto no tienen cita. El mecanismo clima → estrés hídrico → NDVI no puede contrastarse con la base, que no contiene variables climáticas. El problema se plantea como una limitación metodológica (datos discretos frente a continuos), no como un vacío de conocimiento ambiental sobre la cobertura de la Zona Sur. | I26: Citar las cifras (MAATE, PDOT). Formular el vacío ambiental: por ejemplo, que no se ha cuantificado el cambio neto ni el verdor acumulado de la ventana sur en 2019-2024. Presentar la discretización como el reto metodológico que el cálculo resuelve, no como el problema.
A27: 4 | B27: Barbara Salome Saritama Maldonado, Yulian Jeraldine Guaman Aguirre, Kristel Pauleth Cevallos Azanza, Ana Gabriela Medina Yaguana | C27: =Resumen!N8 -> 6.25 | D27: 4 | E27: Hipótesis | F27: Mayor | G27: «…R² ≥ 0,90 … una diferencia inferior al 5 % en comparación con la suma de Riemann… relación entre los períodos de recuperación … y los episodios de sequía estacional.» | H27: (a) El umbral R² ≥ 0,90 no se justifica y es poco realista para un NDVI mensual con nubosidad, y más aún para su derivada r(t). (b) Si el modelo ajusta bien, la coincidencia integral–trapecio < 5 % se cumple casi por construcción: es una verificación numérica, no una hipótesis ambiental. (c) La relación con la sequía no es contrastable porque no hay variables de clima. (d) Un polinomio de grado alto con 72 puntos arriesga sobreajuste. | I27: Separar la hipótesis ambiental (qué se espera del verdor) del criterio de validación del modelo. Justificar los umbrales con la revisión preliminar o con literatura. | J27: Ejemplo orientativo: «El verdor acumulado ∫A(t)dt de los semestres lluviosos supera en al menos X % al de los semestres secos en la ventana sur, 2019-2024» (definir meses y X a partir de la exploración).
A28: 4 | B28: Barbara Salome Saritama Maldonado, Yulian Jeraldine Guaman Aguirre, Kristel Pauleth Cevallos Azanza, Ana Gabriela Medina Yaguana | C28: =Resumen!N8 -> 6.25 | D28: 5 | E28: Objetivos | F28: Mayor | G28: OE3: «…y expresarlo en unidades equivalentes de vegetación o hectáreas acumuladas». | H28: El NDVI es adimensional; su integral tiene unidades de NDVI·mes. No puede expresarse en hectáreas sin un criterio de clasificación (por ejemplo, NDVI > umbral ⇒ vegetación densa) multiplicado por 25 ha/celda. Las «unidades equivalentes de vegetación» no están definidas. | I28: Declarar las unidades de cada integral. Si se quieren hectáreas, definir el umbral y la regla de conversión, y dejar ese cálculo para la Unidad 3 (integrales dobles), como prevé la guía general.
A29: 4 | B29: Barbara Salome Saritama Maldonado, Yulian Jeraldine Guaman Aguirre, Kristel Pauleth Cevallos Azanza, Ana Gabriela Medina Yaguana | C29: =Resumen!N8 -> 6.25 | D29: 6 | E29: Objetivos | F29: Menor | G29: OE1: «Seleccionar la base … auditar … y estructurar la serie…». OG: «un grupo representativo de celdas». | H29: El OE1 es una lista de tareas sin salida explícita. El OG habla de «grupo representativo de celdas», mientras el resto del documento usa las 100 celdas: no se define el criterio de selección. | I29: Indicar la salida del OE1 (tabla de calidad y serie depurada). Definir si se trabaja con las 100 celdas (promedio espacial) o con una submuestra, y con qué criterio.
A30: 4 | B30: Barbara Salome Saritama Maldonado, Yulian Jeraldine Guaman Aguirre, Kristel Pauleth Cevallos Azanza, Ana Gabriela Medina Yaguana | C30: =Resumen!N8 -> 6.25 | D30: 7 | E30: Formato / completitud | F30: Menor | G30: Nombre del archivo: «Relieve_y_Accesibilidad_Territorial__Sur_…pdf»; no hay sección de referencias ni declaración de IA. | H30: El nombre del archivo no corresponde al tema (cobertura vegetal) y faltan referencias, tabla de variables, alcance y matriz de coherencia. Fortalezas: buen resumen, delimitación correcta (y < 9 555 250; 10 × 10 celdas; 25 km²) y notación matemática cuidada. | I30: Nombrar los archivos como Avance2_Grupo04_Cobertura_Sur.pdf. Añadir referencias APA 7 (Sentinel-2, MAATE) y la declaración de uso de IA.
A31: 5 | B31: Shislayne Azucena Chalan Jumbo, Yurixi Maribel Riofrio Medina, Jamileth Stefania Galvez Cornejo, Ibelia Araceli Japon Caillagua, Nelson Sebastian Pullaguari Cuenca | C31: =Resumen!N9 -> 4.75 | D31: 1 | E31: Hipótesis | F31: Crítica | G31: «…el volumen total de agua estimado de esta forma no será igual al que se obtiene simplemente sumando mes a mes, ya que al trabajar con una función continua se refleja mejor cómo cambia la lluvia…» | H31: Es un error conceptual. CHIRPS mensual ya es un acumulado (mm/mes): la suma de los 72 valores mensuales es exactamente la integral de la tasa en el periodo (H = Σ pₖ·Δt con Δt = 1 mes). Un modelo continuo ajustado no «refleja mejor»; introduce error de ajuste. Si conserva masa, su integral debe coincidir con la suma observada. | I31: Usar la suma observada como valor de referencia (verdad de control) y plantear la hipótesis sobre el fenómeno, no sobre el método. El contraste modelo vs. suma es un criterio de validación (error relativo < X %).
A32: 5 | B32: Shislayne Azucena Chalan Jumbo, Yurixi Maribel Riofrio Medina, Jamileth Stefania Galvez Cornejo, Ibelia Araceli Japon Caillagua, Nelson Sebastian Pullaguari Cuenca | C32: =Resumen!N9 -> 4.75 | D32: 2 | E32: Problemática | F32: Mayor | G32: «…la lluvia cambia bastante de un tiempo a otro…», «a veces llueve mucho, a veces poco», «información clara, real y bien hecha». | H32: La redacción es coloquial y repetitiva (un solo párrafo extenso) y no tiene citas. El «problema» se reduce a que «no se ha calculado el total de agua», un vacío trivial que no constituye un problema ambiental. La afirmación «hasta ahora no se ha hecho este tipo de cálculo en la zona» no se sustenta (Valverde et al., 2024, que el propio equipo cita, estiman la precipitación en Loja). | I32: Reescribir con registro técnico: situación hidroclimática de la zona (con cifras citadas) → qué no se conoce (p. ej., el volumen precipitado en la ventana y su contraste estacional) → por qué importa (gestión hídrica) → cómo lo resuelve la integral.
A33: 5 | B33: Shislayne Azucena Chalan Jumbo, Yurixi Maribel Riofrio Medina, Jamileth Stefania Galvez Cornejo, Ibelia Araceli Japon Caillagua, Nelson Sebastian Pullaguari Cuenca | C33: =Resumen!N9 -> 4.75 | D33: 3 | E33: Problemática | F33: Mayor | G33: Delimitación temática: «precipitación CHIRPS, la velocidad del viento, y los días secos y húmedos». | H33: El viento y los días secos/húmedos se anuncian en la delimitación y la justificación, pero no aparecen en la pregunta, la hipótesis ni los objetivos. Es una incoherencia interna. | I33: Incluir solo las variables que se usarán, o justificar su papel como variables de control.
A34: 5 | B34: Shislayne Azucena Chalan Jumbo, Yurixi Maribel Riofrio Medina, Jamileth Stefania Galvez Cornejo, Ibelia Araceli Japon Caillagua, Nelson Sebastian Pullaguari Cuenca | C34: =Resumen!N9 -> 4.75 | D34: 4 | E34: Pregunta | F34: Mayor | G34: «¿Cuál es la lámina acumulada y el volumen total … obtenidos al integrar … p(t), y cómo se relacionan … con la diferencia entre valores extremos de la función acumulada según el Teorema Fundamental del Cálculos?» | H34: (a) Son dos preguntas. (b) El TFC está mal enunciado: ∫ₜ₁ᵗ² p(t) dt = H(t₂) − H(t₁), donde H es la lámina acumulada (una antiderivada). No se trata de «valores extremos» (máximo/mínimo). (c) No se especifica si la lámina es por celda o el promedio de las 100 celdas. Además hay un error ortográfico («Cálculos»). | I34: Dejar una pregunta con magnitud (lámina en mm, volumen en m³), dominio (100 celdas, 25 km²) y periodo (t = 1…72 meses). | J34: Ejemplo orientativo: ¿Cuál es el volumen precipitado V = A·10⁻³·∫₀⁷² p(t) dt (m³) sobre las 100 celdas de la ventana norte entre enero de 2019 y diciembre de 2024, y cómo se distribuye entre semestres húmedos y secos?
A35: 5 | B35: Shislayne Azucena Chalan Jumbo, Yurixi Maribel Riofrio Medina, Jamileth Stefania Galvez Cornejo, Ibelia Araceli Japon Caillagua, Nelson Sebastian Pullaguari Cuenca | C35: =Resumen!N9 -> 4.75 | D35: 5 | E35: Hipótesis | F35: Mayor | G35: «…será bastante mayor en el semestre húmedo…», «…más de 35 millones de metros cúbicos de agua por año». | H35: «Bastante mayor» no tiene umbral y no se definen los meses del semestre húmedo y del seco. El umbral de 35 Mm³/año no se justifica: la ventana mide 100 × 25 ha = 25 km², así que ese volumen equivaldría a una lámina de 1 400 mm/año. Hay que verificar el orden de magnitud. La hipótesis contiene además tres predicciones distintas. | I35: Una sola afirmación con indicador y umbral justificados (literatura o exploración). Definir explícitamente los meses de cada semestre. Verificar dimensionalmente: V [m³] = A [m²] × H [m].
A36: 5 | B36: Shislayne Azucena Chalan Jumbo, Yurixi Maribel Riofrio Medina, Jamileth Stefania Galvez Cornejo, Ibelia Araceli Japon Caillagua, Nelson Sebastian Pullaguari Cuenca | C36: =Resumen!N9 -> 4.75 | D36: 6 | E36: Objetivos | F36: Mayor | G36: OE1: «…entre los años t1=2019 y t2=2024». OE2: «Aplicar el TFC para demostrar … la diferencia p(t2) − P(t1)…». OE3: «Interpretar el significado físico…». | H36: OE1: los límites de integración se expresan en años, pero la base usa t_mes = 1…72; esto genera inconsistencia de unidades. OE2: confunde p (tasa) con P/H (acumulado), y el TFC no se «demuestra» con datos: se aplica o se verifica. OE3: «interpretar» no es medible y no tiene salida. El OG es compuesto y tiene errores de redacción. | I36: Definir t en meses con límites [0, 72]. OE2: «Verificar numéricamente que ∫p dt = H(72) − H(0) con la serie acumulada». OE3: con salida concreta (tabla de lámina y volumen por semestre y año).
A37: 5 | B37: Shislayne Azucena Chalan Jumbo, Yurixi Maribel Riofrio Medina, Jamileth Stefania Galvez Cornejo, Ibelia Araceli Japon Caillagua, Nelson Sebastian Pullaguari Cuenca | C37: =Resumen!N9 -> 4.75 | D37: 7 | E37: Formato / completitud | F37: Mayor | G37: Secciones 7 (Datos y variables), 8 (Alcance), 9 (Matriz de coherencia) y anexo IA con texto de plantilla («nombre_1 …»). | H37: Se entregaron secciones de plantilla sin completar. Las citas en el texto no siguen el formato APA (faltan paréntesis: «…agropecuarias Valverde et al., 2024»). | I37: Completar las secciones con los nombres reales de las columnas y corregir el formato de cita: (Valverde et al., 2024).
A38: 5 | B38: Shislayne Azucena Chalan Jumbo, Yurixi Maribel Riofrio Medina, Jamileth Stefania Galvez Cornejo, Ibelia Araceli Japon Caillagua, Nelson Sebastian Pullaguari Cuenca | C38: =Resumen!N9 -> 4.75 | D38: 8 | E38: Entrega | F38: Administrativa | G38: Se recibieron dos archivos (informe_parte1-1.pdf e informe_parte_matemática 2.pdf). | H38: Los dos archivos tienen contenido idéntico. | I38: Entregar un solo archivo con nombre normalizado (Avance2_Grupo05_Clima_Norte.pdf).
A39: 6 | B39: Sara Lissette Criollo Montalvan, Lady Lissethe Medina Gualan, Lisseth Alexandra Salazar Valdiviezo, Alejandra Nicole Verdesoto Ortiz, Lisbeth Liliana Sandoval Mendoza | C39: =Resumen!N10 -> 2 | D39: 1 | E39: Completitud | F39: Crítica | G39: El documento contiene solo: delimitación, pregunta, tabla de variables y tabla de unidades. | H39: No se presentan el planteamiento del problema ambiental, la justificación, la hipótesis ni los objetivos (general y específicos), exigidos para la Unidad 1 (guía general, sección 4.4). Faltan las referencias y la declaración de uso de IA (el PDF fue generado con OpenAI Prism). | I39: Redactar las cuatro secciones faltantes siguiendo la guía del Avance 2. Declarar el uso de IA: herramienta, propósito, qué se verificó y qué se reescribió.
A40: 6 | B40: Sara Lissette Criollo Montalvan, Lady Lissethe Medina Gualan, Lisseth Alexandra Salazar Valdiviezo, Alejandra Nicole Verdesoto Ortiz, Lisbeth Liliana Sandoval Mendoza | C40: =Resumen!N10 -> 2 | D40: 2 | E40: Problemática | F40: Crítica | G40: No presentada (solo la «Delimitación del problema», que es correcta: 100 celdas, 2 500 ha, 72 meses, excluye 2025 y la Zona Norte). | H40: Sin un problema ambiental no hay justificación para la pregunta. La delimitación es una fortaleza que debe conservarse. | I40: Problema: situación hidroclimática de la zona sur (citada) → vacío (volumen precipitado en el periodo crítico no cuantificado) → relevancia (gestión hídrica, escorrentía) → resolución con la integral de la tasa.
A41: 6 | B41: Sara Lissette Criollo Montalvan, Lady Lissethe Medina Gualan, Lisseth Alexandra Salazar Valdiviezo, Alejandra Nicole Verdesoto Ortiz, Lisbeth Liliana Sandoval Mendoza | C41: =Resumen!N10 -> 2 | D41: 3 | E41: Hipótesis | F41: Crítica | G41: No presentada. | H41: Sin hipótesis no hay afirmación contrastable. | I41: Plantear una afirmación con indicador y umbral justificados, por ejemplo sobre la fracción de la lámina anual que se concentra en la ventana crítica, o sobre su ubicación estacional. El umbral debe justificarse con literatura o con la exploración preliminar.
...

Sheet Grupo 1
A1: Revisión del Avance 1 – Grupo 1
A2: Matemática II · Proyecto Integrador · Revisión con criterio Q1 · 16-oct-2026
A4: Integrantes | C4: Jhanine Fernanda Toledo Merino, Mayerly Stefanny Moreno Vera, Mateo Joel Gonzalez Samaniego, Dulce Isabel Barreto Zapata
A5: Tema y zona oficial | C5: Relieve y accesibilidad – Zona Norte (Grupo_01_Relieve_Norte.csv)
A6: Declarado en el informe | C6: —
A7: Archivo revisado | C7: No se encontró entrega en la carpeta avance_1
A8: Dictamen | C8: Sin entrega — Problemática: No presentado · Pregunta: No presentado · Hipótesis: No presentado · Objetivos: No presentado
A9: Calificación (/10) | C9: =Resumen!N5 -> 0
A10: Desglose de la calificación | C10: ="Problemática "&FIXED(Resumen!G5,2)&" · Pregunta "&FIXED(Resumen!I5,2)&" · Hipótesis "&FIXED(Resumen!K5,2)&" · Objetivos "&FIXED(Resumen!M5,2)&" (cada uno sobre 2,5) · Equivalencia Fase 1: "&FIXED(Resumen!O5,2)&" / 0,30" -> Problemática 0.00 · Pregunta 0.00 · Hipótesis 0.00 · Objetivos 0.00 (cada uno sobre 2,5) · Equivalencia Fase 1: 0.00 / 0,30
A11: Prioridades para el Avance 2 | C11: Entregar en el Avance 2 la formulación completa (problema, pregunta, hipótesis, objetivos) junto con los componentes propios del Avance 2.
A13: N.º | B13: Elemento | C13: Severidad | D13: Evidencia en el informe | E13: Error o debilidad detectada | F13: Sugerencia para el Avance 2 | G13: Ejemplo orientativo (adaptar, no copiar)
A14: 1 | B14: General | C14: Crítica | D14: No existe archivo del grupo en Unidad_1/avance_proyecto_integrador/avance_1. | E14: No hay evidencia del Avance 1: no puede evaluarse problemática, pregunta, hipótesis ni objetivos. | F14: Si la entrega se realizó por otro medio (EVA, correo), comunicarlo al docente. Caso contrario, el Avance 2 debe incluir la formulación completa: problema, pregunta, hipótesis y objetivos, siguiendo la guía general (sección 4.4, Unidad 1) y la guía del Avance 2.
A15: 2 | B15: Orientación | C15: Administrativa | D15: Tema asignado: relieve y accesibilidad, Zona Norte (400 celdas estáticas). | E15: — | F15: Recuerden que las variables de relieve son estáticas (una fila por celda): no tienen dimensión temporal. La guía general orienta el trabajo hacia el área bajo el perfil de elevación de un transecto, A = ∫ f(x) dx.

Sheet Grupo 2
A1: Revisión del Avance 1 – Grupo 2
A2: Matemática II · Proyecto Integrador · Revisión con criterio Q1 · 16-oct-2026
A4: Integrantes | C4: Yanira Maily Rojas Vega, Sonia Noemi Rodriguez Jaramillo, Carlos Daniel Gonzalez Castillo, Diana Patricia Cardenas Campoverde
A5: Tema y zona oficial | C5: Relieve y accesibilidad – Zona Sur (Grupo_02_Relieve_Sur.csv)
A6: Declarado en el informe | C6: «Equipo N.º 1» – Relieve, Zona Norte
A7: Archivo revisado | C7: Proyecto_de_integracion_grupo_1_Matematicas (1).pdf
A8: Dictamen | C8: Revisión mayor — Problemática: Revisión mayor · Pregunta: Reformular · Hipótesis: Reformular · Objetivos: Revisión mayor
A9: Calificación (/10) | C9: =Resumen!N6 -> 3.75
A10: Desglose de la calificación | C10: ="Problemática "&FIXED(Resumen!G6,2)&" · Pregunta "&FIXED(Resumen!I6,2)&" · Hipótesis "&FIXED(Resumen!K6,2)&" · Objetivos "&FIXED(Resumen!M6,2)&" (cada uno sobre 2,5) · Equivalencia Fase 1: "&FIXED(Resumen!O6,2)&" / 0,30" -> Problemática 1.25 · Pregunta 0.75 · Hipótesis 0.75 · Objetivos 1.00 (cada uno sobre 2,5) · Equivalencia Fase 1: 0.11 / 0,30
A11: Prioridades para el Avance 2 | C11: 1) Confirmar grupo, zona y base. 2) Reescribir pregunta, hipótesis y objetivos en clave de cálculo integral (perfil de elevación de un transecto). 3) Eliminar lo que la base no mide (inundaciones, recarga hídrica, rutas reales).
A13: N.º | B13: Elemento | C13: Severidad | D13: Evidencia en el informe | E13: Error o debilidad detectada | F13: Sugerencia para el Avance 2 | G13: Ejemplo orientativo (adaptar, no copiar)
A14: 1 | B14: Asignación | C14: Crítica | D14: Portada: «Equipo N.º 1 … parte norte del cantón Loja». | E14: En la nómina oficial (Grupos_matematica.xlsx y Cuadro 1 de la guía general) el grupo figura como GRUPO 2, con el tema Relieve y la Zona SUR. El informe se declara Equipo 1 y trabaja la Zona Norte. | F14: Confirmar con el docente el número de grupo y la base asignada antes del Avance 2. Si corresponde la Zona Sur, rehacer la delimitación con Grupo_02_Relieve_Sur.csv (centro_y_m < 9 555 250).
A15: 2 | B15: Problemática | C15: Mayor | D15: Enumera cuatro causas: expansión urbana, escorrentía, inundaciones en zonas bajas y accesibilidad; menciona recarga hídrica, calidad del agua y caudal pico. | E15: El problema es descriptivo y disperso: mezcla fenómenos que la base no mide (escorrentía, inundaciones, recarga de acuíferos, expansión urbana, calidad del agua). La base contiene solo elevación, pendiente, orientación y distancias a vías y asentamientos, todas estáticas. El lector no identifica cuál es el problema investigable. | F15: Reducir el problema a una sola cadena: situación territorial (relieve quebrado) → vacío (no se ha cuantificado la sección transversal ni el desnivel acumulado de un transecto representativo) → relevancia → posibilidad de calcularlo con la base. Eliminar las causas que no pueden contrastarse con los datos.
A16: 3 | B16: Problemática | C16: Mayor | D16: «Altitudes desde 2,400 m s.n.m. hasta 3,200+ m», «precipitación anual 900-1,200 mm», «temperaturas medias entre 9 °C y 16 °C». | E16: Son cifras de contexto sin cita, y contradicen la base: en la ventana Norte (Grupo_01_Relieve_Norte.csv) la elevación media por celda va de ≈1 643 m a ≈3 292 m. Además se listan siete parroquias (San Lucas, Santiago, Gualel, Taquil, Chantaco, Chuquiribamba, El Cisne) que no corresponden a una ventana de 10 × 10 km. | F16: Citar toda cifra de contexto (APA 7) y describir la zona con los datos reales de la ventana (rango de elevación, pendiente media, coordenadas). Delimitar el área a la ventana de 20 × 20 celdas, no a parroquias completas.
A17: 4 | B17: Pregunta | C17: Mayor | D17: «¿Cómo influyen las características del terreno en el acceso a las diferentes zonas del norte de Loja durante el periodo 2019-2024…?» | E17: (a) La pregunta es causal y abierta («¿cómo influyen?»), no se responde con un número. (b) No está planteada en clave de cálculo integral: no hay función, intervalo ni integral, y la rúbrica de la Fase 1 lo exige. (c) «Accesibilidad» no está definida operativamente. (d) El periodo 2019-2024 no aplica: el relieve es estático. | F17: Formular una pregunta única, cuantitativa y respondible con una integral definida sobre un transecto de la ventana. | G17: Ejemplo orientativo (adaptar): ¿Cuál es el área de la sección transversal bajo el perfil de elevación del transecto [fila/columna] de la ventana [zona], A = ∫ₐᵇ f(x) dx (m²), y cuánto difiere su valor analítico de la aproximación trapezoidal con los 20 puntos observados?
A18: 5 | B18: Hipótesis | C18: Mayor | D18: «…influyen de forma significativa en la accesibilidad… presentan mayores limitaciones de acceso (rutas más largas y sinuosas, con una distancia real mayor que la euclidiana)…» | E18: (a) «Significativa» no tiene indicador, umbral ni prueba asociados. (b) La base no contiene rutas ni distancias recorridas: solo la distancia euclidiana a la vía más cercana (osm_distancia_vias_m_mean). La comparación distancia real vs. euclidiana no es contrastable. (c) «Se concentran en sectores específicos que pueden localizarse» no es falsable. | F18: Escribir una afirmación con variable, transecto, indicador y criterio cuantitativo justificado. Si se mantiene la accesibilidad, operacionalizarla con osm_distancia_vias_m_mean y pendiente, y dejar la longitud de arco para la Unidad 2. | G18: Ejemplo orientativo: «Un polinomio de grado ≤ 4 ajustado al perfil del transecto reproduce la elevación con R² ≥ 0,95, y su integral difiere menos de 2 % de la suma trapezoidal con Δx = 500 m».
A19: 6 | B19: Objetivos | C19: Mayor | D19: OG «Analizar cómo las características del relieve influyen…»; OE «Reconocer…», «Analizar cómo se relacionan…», «Localizar las áreas…». | E19: Los verbos no son medibles y ningún objetivo produce una salida verificable (tabla, valor, figura). El OG repite la pregunta. Ningún objetivo menciona un modelo f(x), una integral definida, sumas de Riemann o el TFC: el proyecto no demanda cálculo integral. | F19: OG en infinitivo, alineado con la nueva pregunta. Tres OE con salida verificable: (1) seleccionar y justificar el transecto (perfil observado); (2) ajustar f(x) y reportar R²/RMSE; (3) calcular ∫ f(x) dx analíticamente y compararla con Riemann/trapecio (error relativo %).
A20: 7 | B20: Formato / completitud | C20: Mayor | D20: Las secciones 6 (Datos y variables), 7 (Alcance), 8 (Matriz de coherencia) y el anexo de IA conservan el texto de plantilla («nombre 1 …», «Qué incluye y qué no…»). | E20: El documento se entregó con secciones de plantilla sin completar. | F20: Completar o retirar toda sección de plantilla. La matriz de coherencia es especialmente útil para verificar que pregunta, hipótesis y OG traten la misma variable.
A21: 8 | B21: Referencias | C21: Mayor | D21: INAMHI (2020) Anuario Meteorológico; GAD Provincial (2021) PDOT; Cueva y Jiménez (2019) «…sector sur del cantón Loja», Revista de Geografía y Ciencias Ambientales – UNL. | E21: No hay citas en el texto. El anuario meteorológico no sustenta afirmaciones sobre relieve. La referencia de Cueva y Jiménez (2019) trata el sector sur y no pudo localizarse; debe verificarse que exista. No se citan las fuentes de los datos (ALOS, OSM, GHSL). | F21: Citar en el texto cada afirmación con su fuente; incluir solo referencias consultadas y localizables (DOI/URL), y citar la base y el diccionario de variables del curso.
A22: 9 | B22: Problemática | C22: Menor | D22: Las secciones 1 y 2 repiten casi literalmente los mismos párrafos (expansión urbana, erosión, accesibilidad). | E22: Hay redundancia entre problema y justificación; la lista numerada está incrustada en el párrafo, con errores de tipeo («rígos») y de puntuación. | F22: El problema explica qué falta conocer; la justificación explica por qué importa. No repetir. Usar listas de LaTeX (enumerate) o redactar en prosa.

Sheet Grupo 3
A1: Revisión del Avance 1 – Grupo 3
A2: Matemática II · Proyecto Integrador · Revisión con criterio Q1 · 16-oct-2026
A4: Integrantes | C4: John David Jimenez Troya, Isidro Francisco Chamba Mendoza, Andy Alcides Aguilar Arteaga, Giorgi Michael Chamba Sanchez, Kevin Josue Jimenez Macau
A5: Tema y zona oficial | C5: Cobertura vegetal y uso del suelo – Zona Norte (Grupo_03_Cobertura_Norte.csv)
A6: Declarado en el informe | C6: «Equipo N.º 2» – Relieve, Zona Sur
A7: Archivo revisado | C7: Avance_Proyecto_Matematicas_Grupo2 (1).pdf
A8: Dictamen | C8: Revisión mayor — Problemática: Reformular · Pregunta: Reformular · Hipótesis: Reformular · Objetivos: Revisión mayor
A9: Calificación (/10) | C9: =Resumen!N7 -> 4.25
A10: Desglose de la calificación | C10: ="Problemática "&FIXED(Resumen!G7,2)&" · Pregunta "&FIXED(Resumen!I7,2)&" · Hipótesis "&FIXED(Resumen!K7,2)&" · Objetivos "&FIXED(Resumen!M7,2)&" (cada uno sobre 2,5) · Equivalencia Fase 1: "&FIXED(Resumen!O7,2)&" / 0,30" -> Problemática 1.00 · Pregunta 0.75 · Hipótesis 1.00 · Objetivos 1.50 (cada uno sobre 2,5) · Equivalencia Fase 1: 0.13 / 0,30
A11: Prioridades para el Avance 2 | C11: 1) Confirmar grupo, tema y base. 2) Abandonar la «variación mensual de la pendiente» (variable estática: vale 0). 3) Reconstruir la formulación desde el OE3 (integral del perfil de un transecto) o desde el tema oficial.
A13: N.º | B13: Elemento | C13: Severidad | D13: Evidencia en el informe | E13: Error o debilidad detectada | F13: Sugerencia para el Avance 2 | G13: Ejemplo orientativo (adaptar, no copiar)
A14: 1 | B14: Asignación | C14: Crítica | D14: Portada: «Equipo N.º 2 … zona sur»; tema relieve y movilidad. | E14: En la nómina oficial el grupo es el GRUPO 3, con el tema Cobertura vegetal y uso del suelo, Zona NORTE. El informe trabaja relieve en la Zona Sur, tema asignado a otro grupo (en la guía general, la regla territorial prohíbe cruzar datos entre zonas o equipos). | F14: Confirmar con el docente el tema y la base. Si se mantiene la asignación oficial, el Avance 2 debe reformularse sobre Grupo_03_Cobertura_Norte.csv.
A15: 2 | B15: Datos | C15: Crítica | D15: «base asignada al equipo 02 (3.996 celdas y 66 columnas)», «base mensual», variables dem_mean, slope_mean, dist_vias_m, dist_asentamientos_m. | E15: Se utilizó la base antigua (origen2), no la vigente. La base vigente de relieve tiene 400 celdas × 17 columnas, sin dimensión temporal, y sus columnas se llaman alos_elevacion_m_mean, alos_pendiente_grados_mean, osm_distancia_vias_m_mean y ghsl_distancia_asentamiento_m_mean. Las variables citadas no existen en ninguna base del curso. | F15: Trabajar únicamente con la base vigente de Unidad_1/base_de_datos y transcribir los nombres exactos de columna desde DICCIONARIO_VARIABLES.csv.
A16: 3 | B16: Problemática | C16: Crítica | D16: «…se propone cuantificar los cambios mensuales de esa variable [pendiente] en cada celda…» | E16: La premisa es físicamente inválida: la pendiente proviene de un modelo digital de elevación estático (ALOS). En la base antigua el valor se repetía cada mes, así que |s_i,t − s_i,t−1| = 0 y V_i = 0 en todas las celdas. No existe un fenómeno que medir: la pregunta, la hipótesis y el OE2 no son respondibles. | F16: Descartar la «variación acumulada de la pendiente». Un problema viable con relieve es la caracterización integral de un transecto (área de la sección transversal, desnivel). Con cobertura, el problema es el cambio acumulado del NDVI.
A17: 4 | B17: Pregunta | C17: Mayor | D17: «¿Qué asociación existe entre la variación acumulada de la pendiente media … y la distancia a las vías…?» | E17: (a) Depende de una variable con varianza nula, así que la correlación queda indefinida. (b) Es una pregunta estadística, no de cálculo integral: la integral aparece solo en el OE3. (c) Hay incoherencia: el OG incluye la integral del transecto, pero la pregunta y la hipótesis no. | F17: Reformular la pregunta alrededor de la integral definida (la parte más sólida del documento es el OE3). | G17: Ejemplo orientativo (si se confirma relieve): ¿Cuál es el área de la sección transversal ∫ₐᵇ f(x) dx bajo el perfil de elevación de un transecto desde el punto más bajo hasta la cumbre de la ventana, y cuál es el error relativo de las sumas de Riemann con n = 19 subintervalos?
A18: 5 | B18: Hipótesis | C18: Mayor | D18: «…se asocia positivamente con la distancia a las vías… r ≥ 0,30 y p < 0,05.» | E18: Tiene una buena estructura formal (indicador, umbral y criterio de significancia), pero se aplica a una variable inexistente. El umbral r ≥ 0,30 no se justifica. Con celdas vecinas, la dependencia espacial infla el valor p (el equipo lo reconoce, pero no lo resuelve). | F18: Conservar la estructura (indicador + umbral + criterio) y aplicarla a una magnitud integral. Justificar el umbral con literatura o con la revisión preliminar.
A19: 6 | B19: Objetivos | C19: Mayor | D19: OG compuesto: «Cuantificar… y analizar… complementando con la integral definida…». OE1: revisar estructura y calidad. OE3: transecto, f(x), antiderivada y Riemann. | E19: El OG reúne tres metas distintas. El OE1 es una tarea (revisión de datos) sin salida explícita. El OE2 es inviable. El OE3 está bien construido: tiene intervalo, nivel de referencia, antiderivada, comparación con Riemann e interpretación física. | F19: Construir el OG a partir del OE3. Expresar el OE1 como salida (tabla de control de calidad). Reemplazar el OE2 por el ajuste y la validación del modelo f(x) (R², RMSE).
A20: 7 | B20: Formato / completitud | C20: Mayor | D20: El documento termina en el anexo de IA; no hay referencias, tabla de variables, alcance ni matriz de coherencia. Anexo IA: «El equipo debe verificar la exactitud de los datos…». | E20: No hay ninguna referencia bibliográfica ni cita. La declaración de IA está redactada como una instrucción dirigida al equipo (parece texto generado y no editado), no como una declaración de lo que el equipo verificó. | F20: Incluir referencias APA 7 localizables y la tabla de variables con nombres reales. Reescribir el anexo de IA en primera persona del plural: qué herramienta se usó, para qué, qué se verificó y qué se reescribió.
A21: 8 | B21: Problemática | C21: Menor | D21: Redacción cuidadosa: distingue asociación de causalidad y declara qué no mide la base. | E21: Fortaleza que debe conservarse. Sin embargo, el problema no establece un vacío de conocimiento ambiental, sino un procedimiento de cálculo. | F21: Mantener el tono prudente y explicitar el vacío: qué no se sabe del territorio y por qué una integral lo resuelve.

Sheet Grupo 4
A1: Revisión del Avance 1 – Grupo 4
A2: Matemática II · Proyecto Integrador · Revisión con criterio Q1 · 16-oct-2026
A4: Integrantes | C4: Barbara Salome Saritama Maldonado, Yulian Jeraldine Guaman Aguirre, Kristel Pauleth Cevallos Azanza, Ana Gabriela Medina Yaguana
A5: Tema y zona oficial | C5: Cobertura vegetal y uso del suelo – Zona Sur (Grupo_04_Cobertura_Sur.csv)
A6: Declarado en el informe | C6: «Equipo N.º 4» – Cobertura vegetal, Zona Sur (coincide)
A7: Archivo revisado | C7: Relieve_y_Accesibilidad_Territorial__Sur_ (1) (2).pdf
A8: Dictamen | C8: Revisión mayor — Problemática: Revisión mayor · Pregunta: Reformular · Hipótesis: Revisión mayor · Objetivos: Revisión menor
A9: Calificación (/10) | C9: =Resumen!N8 -> 6.25
A10: Desglose de la calificación | C10: ="Problemática "&FIXED(Resumen!G8,2)&" · Pregunta "&FIXED(Resumen!I8,2)&" · Hipótesis "&FIXED(Resumen!K8,2)&" · Objetivos "&FIXED(Resumen!M8,2)&" (cada uno sobre 2,5) · Equivalencia Fase 1: "&FIXED(Resumen!O8,2)&" / 0,30" -> Problemática 1.50 · Pregunta 1.25 · Hipótesis 1.50 · Objetivos 2.00 (cada uno sobre 2,5) · Equivalencia Fase 1: 0.19 / 0,30
A11: Prioridades para el Avance 2 | C11: 1) Distinguir A(t) (NDVI observado) de r(t) (tasa). 2) Declarar y tratar los NDVI faltantes (ninguna celda tiene 72 meses). 3) Convertir la hipótesis en una afirmación ambiental con umbral justificado.
A13: N.º | B13: Elemento | C13: Severidad | D13: Evidencia en el informe | E13: Error o debilidad detectada | F13: Sugerencia para el Avance 2 | G13: Ejemplo orientativo (adaptar, no copiar)
A14: 1 | B14: Datos | C14: Crítica | D14: «…un período ininterrumpido de 72 meses … 7.200 registros», «a partir de los 72 registros mensuales disponibles». | E14: Es falso para el NDVI: faltan 1 412 de 7 200 valores (19,6 %), ninguna celda tiene los 72 meses completos (el mínimo es 46) y en 2019-01, 2023-03 y 2023-05 falta el NDVI en las 100 celdas. El ajuste y las integrales dependen críticamente de cómo se traten estos huecos. | F14: Cuantificar los faltantes por mes y por celda (sentinel_t1_missing, s2_cobertura_valida_pct) y declarar el tratamiento: excluir, promediar espacialmente las celdas válidas o interpolar con justificación. Reportar cuántas observaciones entran en cada cálculo.
A15: 2 | B15: Pregunta | C15: Crítica | D15: «¿Cuál es la variación neta acumulada … A_veg = ∫ r(t) dt …? Asimismo, ¿qué grado de concordancia existe entre … sumas de Riemann … y … el TFC, utilizando un modelo continuo r(t)…?» | E15: (a) Son dos preguntas. (b) Hay una confusión conceptual entre A(t) y r(t): la base observa el nivel A(t) (NDVI), no la tasa r(t). Por el TFC, ∫r dt = A(72) − A(1): el «cambio neto» se reduce a la diferencia entre dos meses ruidosos (y uno de ellos, 2019-01, no tiene datos). (c) Para aplicar Riemann a r(t) primero hay que construir r a partir de diferencias finitas, y eso no se explica. | F15: Elegir una sola formulación coherente: (a) integrar el NDVI observado, V = ∫ A(t) dt [NDVI·mes] («verdor acumulado»), y comparar el modelo continuo con el trapecio; o (b) definir r(t) ≈ ΔA/Δt, modelarla y verificar el TFC con A(t₂) − A(t₁) usando promedios de periodo en lugar de meses aislados. Dejar una sola pregunta.
A16: 3 | B16: Problemática | C16: Mayor | D16: «Este cantón abarca alrededor de 1.928 km² … agrícolas (31 %), bosque nativo (26 %), matorrales (17 %)…». «…las fluctuaciones … de la temperatura y la precipitación provocan períodos de escasez de agua que pueden impactar … la actividad fotosintética…» | E16: Las cifras de contexto no tienen cita. El mecanismo clima → estrés hídrico → NDVI no puede contrastarse con la base, que no contiene variables climáticas. El problema se plantea como una limitación metodológica (datos discretos frente a continuos), no como un vacío de conocimiento ambiental sobre la cobertura de la Zona Sur. | F16: Citar las cifras (MAATE, PDOT). Formular el vacío ambiental: por ejemplo, que no se ha cuantificado el cambio neto ni el verdor acumulado de la ventana sur en 2019-2024. Presentar la discretización como el reto metodológico que el cálculo resuelve, no como el problema.
